[2021-05-16 04:51:14,137] {taskinstance.py:877} INFO - Dependencies all met for <TaskInstance: Assignment1_Q2.toJSON 2021-05-16T04:46:01.875642+00:00 [queued]>
[2021-05-16 04:51:14,197] {taskinstance.py:877} INFO - Dependencies all met for <TaskInstance: Assignment1_Q2.toJSON 2021-05-16T04:46:01.875642+00:00 [queued]>
[2021-05-16 04:51:14,198] {taskinstance.py:1068} INFO - 
--------------------------------------------------------------------------------
[2021-05-16 04:51:14,198] {taskinstance.py:1069} INFO - Starting attempt 2 of 2
[2021-05-16 04:51:14,198] {taskinstance.py:1070} INFO - 
--------------------------------------------------------------------------------
[2021-05-16 04:51:14,214] {taskinstance.py:1089} INFO - Executing <Task(PythonOperator): toJSON> on 2021-05-16T04:46:01.875642+00:00
[2021-05-16 04:51:14,221] {standard_task_runner.py:52} INFO - Started process 80 to run task
[2021-05-16 04:51:14,226] {standard_task_runner.py:76} INFO - Running: ['airflow', 'tasks', 'run', 'Assignment1_Q2', 'toJSON', '2021-05-16T04:46:01.875642+00:00', '--job-id', '13', '--pool', 'default_pool', '--raw', '--subdir', 'DAGS_FOLDER/dag.py', '--cfg-path', '/tmp/tmpwhun7teg', '--error-file', '/tmp/tmphs8baa92']
[2021-05-16 04:51:14,227] {standard_task_runner.py:77} INFO - Job 13: Subtask toJSON
[2021-05-16 04:51:14,359] {logging_mixin.py:104} INFO - Running <TaskInstance: Assignment1_Q2.toJSON 2021-05-16T04:46:01.875642+00:00 [running]> on host 41381ab19f3b
[2021-05-16 04:51:14,535] {taskinstance.py:1283} INFO - Exporting the following env vars:
AIRFLOW_CTX_DAG_OWNER=GhaydaHyasat
AIRFLOW_CTX_DAG_ID=Assignment1_Q2
AIRFLOW_CTX_TASK_ID=toJSON
AIRFLOW_CTX_EXECUTION_DATE=2021-05-16T04:46:01.875642+00:00
AIRFLOW_CTX_DAG_RUN_ID=manual__2021-05-16T04:46:01.875642+00:00
[2021-05-16 04:51:14,601] {taskinstance.py:1482} ERROR - Task failed with exception
Traceback (most recent call last):
  File "/home/airflow/.local/lib/python3.6/site-packages/airflow/models/taskinstance.py", line 1138, in _run_raw_task
    self._prepare_and_execute_task_with_callbacks(context, task)
  File "/home/airflow/.local/lib/python3.6/site-packages/airflow/models/taskinstance.py", line 1311, in _prepare_and_execute_task_with_callbacks
    result = self._execute_task(context, task_copy)
  File "/home/airflow/.local/lib/python3.6/site-packages/airflow/models/taskinstance.py", line 1341, in _execute_task
    result = task_copy.execute(context=context)
  File "/home/airflow/.local/lib/python3.6/site-packages/airflow/operators/python.py", line 117, in execute
    return_value = self.execute_callable()
  File "/home/airflow/.local/lib/python3.6/site-packages/airflow/operators/python.py", line 128, in execute_callable
    return self.python_callable(*self.op_args, **self.op_kwargs)
  File "/opt/airflow/dags/dag.py", line 40, in tojson
    df = pd.read_csv('/home/airflow/data/' + str(id) + '.csv')
  File "/home/airflow/.local/lib/python3.6/site-packages/pandas/io/parsers.py", line 688, in read_csv
    return _read(filepath_or_buffer, kwds)
  File "/home/airflow/.local/lib/python3.6/site-packages/pandas/io/parsers.py", line 454, in _read
    parser = TextFileReader(fp_or_buf, **kwds)
  File "/home/airflow/.local/lib/python3.6/site-packages/pandas/io/parsers.py", line 948, in __init__
    self._make_engine(self.engine)
  File "/home/airflow/.local/lib/python3.6/site-packages/pandas/io/parsers.py", line 1180, in _make_engine
    self._engine = CParserWrapper(self.f, **self.options)
  File "/home/airflow/.local/lib/python3.6/site-packages/pandas/io/parsers.py", line 2010, in __init__
    self._reader = parsers.TextReader(src, **kwds)
  File "pandas/_libs/parsers.pyx", line 382, in pandas._libs.parsers.TextReader.__cinit__
  File "pandas/_libs/parsers.pyx", line 674, in pandas._libs.parsers.TextReader._setup_parser_source
FileNotFoundError: [Errno 2] No such file or directory: '/home/airflow/data/None.csv'
[2021-05-16 04:51:14,620] {taskinstance.py:1532} INFO - Marking task as FAILED. dag_id=Assignment1_Q2, task_id=toJSON, execution_date=20210516T044601, start_date=20210516T045114, end_date=20210516T045114
[2021-05-16 04:51:14,724] {local_task_job.py:146} INFO - Task exited with return code 1
